Workbook

Sheet BALANCE SHEET
A1: A2 - E CHARGING & BATTERY SWAPPING - REVENUE PROJECTION
A2: DESCRIPTION | B2: UNIT | C2: CY-2026 | D2: CY-2027 | E2: CY-2028 | F2: CY-2029 | G2: CY-2030 | H2: CY-2031 | I2: CY-2032 | J2: CY-2033 | K2: CY-2034 | L2: CY-2035 | M2: CY-2036 | N2: CY-2037
A3: ASSETS
A4: CURRENT ASSETS
A5: CASH & CASH EQUAVALENTS | B5: USD | C5: ='CASH FLOW'!C22 -> 9000000 | D5: ='CASH FLOW'!D22 -> 15267233 | E5: ='CASH FLOW'!E22 -> 20503037 | F5: ='CASH FLOW'!F22 -> 30204125 | G5: ='CASH FLOW'!G22 -> 45344503 | H5: ='CASH FLOW'!H22 -> 66901321 | I5: ='CASH FLOW'!I22 -> 95591197 | J5: ='CASH FLOW'!J22 -> 1.3261112e+08 | ... N5: ='CASH FLOW'!N22 -> 3.0214787e+08
A6: TOTAL CURRENT ASSETS | B6: USD | C6: =C5 -> 9000000 | D6: =D5 -> 15267233 | E6: =E5 -> 20503037 | F6: =F5 -> 30204125 | G6: =G5 -> 45344503 | H6: =H5 -> 66901321 | I6: =I5 -> 95591197 | J6: =J5 -> 1.3261112e+08 | ... N6: =N5 -> 3.0214787e+08
A8: NON-CURRENT ASSETS
A9: CHARGING/SWAPPING STATIONS | B9: USD | C9: ='CAPEX & DEPRECIATION'!E3 -> 7000000 | D9: ='CAPEX & DEPRECIATION'!F49 -> 6416666.7 | E9: ='CAPEX & DEPRECIATION'!G49 -> 5833333.3 | F9: ='CAPEX & DEPRECIATION'!H49 -> 5250000 | G9: ='CAPEX & DEPRECIATION'!I49 -> 4666666.7 | H9: ='CAPEX & DEPRECIATION'!J49 -> 4083333.3 | I9: ='CAPEX & DEPRECIATION'!K49 -> 3500000 | J9: ='CAPEX & DEPRECIATION'!L49 -> 2916666.7 | K9: ='CAPEX & DEPRECIATION'!M49 -> 2916666.7 | ... N9: ='CAPEX & DEPRECIATION'!P49 -> 2916666.7
A10: CHARGERS | B10: USD | C10: ='CAPEX & DEPRECIATION'!E4 -> 10200000 | D10: ='CAPEX & DEPRECIATION'!F50 -> 9350000 | E10: ='CAPEX & DEPRECIATION'!G50 -> 27200000 | F10: ='CAPEX & DEPRECIATION'!H50 -> 52700000 | G10: ='CAPEX & DEPRECIATION'!I50 -> 85000000 | H10: ='CAPEX & DEPRECIATION'!J50 -> 123250000 | I10: ='CAPEX & DEPRECIATION'!K50 -> 167450000 | J10: ='CAPEX & DEPRECIATION'!L50 -> 155650000 | K10: ='CAPEX & DEPRECIATION'!M50 -> 1.3269167e+08 | ... N10: ='CAPEX & DEPRECIATION'!P50 -> 63816667
A11: SOFTWARE & PLATFORM DEVELOPMENT | B11: USD | C11: ='CAPEX & DEPRECIATION'!E6 -> 1000000 | D11: ='CAPEX & DEPRECIATION'!F52 -> 875000 | E11: ='CAPEX & DEPRECIATION'!G52 -> 1187500 | F11: ='CAPEX & DEPRECIATION'!H52 -> 1437500 | G11: ='CAPEX & DEPRECIATION'!I52 -> 1625000 | H11: ='CAPEX & DEPRECIATION'!J52 -> 1750000 | I11: ='CAPEX & DEPRECIATION'!K52 -> 1375000 | J11: ='CAPEX & DEPRECIATION'!L52 -> 1000000 | K11: ='CAPEX & DEPRECIATION'!M52 -> 625000 | ... N11: ='CAPEX & DEPRECIATION'!P52 -> 0
A12: HARDWARE & OFFICE EQUIPMENT | B12: USD | C12: ='CAPEX & DEPRECIATION'!E7 -> 2000000 | D12: ='CAPEX & DEPRECIATION'!F53 -> 1800000 | E12: ='CAPEX & DEPRECIATION'!G53 -> 1600000 | F12: ='CAPEX & DEPRECIATION'!H53 -> 1400000 | G12: ='CAPEX & DEPRECIATION'!I53 -> 1200000 | H12: ='CAPEX & DEPRECIATION'!J53 -> 1000000 | I12: ='CAPEX & DEPRECIATION'!K53 -> 800000 | J12: ='CAPEX & DEPRECIATION'!L53 -> 600000 | K12: ='CAPEX & DEPRECIATION'!M53 -> 400000 | ... N12: ='CAPEX & DEPRECIATION'!P53 -> 0
A13: TOTAL NON-CURRENT ASSETS | B13: USD | C13: =SUM(C9:C12) -> 20200000 | D13: =SUM(D9:D12) -> 18441667 | E13: =SUM(E9:E12) -> 35820833 | F13: =SUM(F9:F12) -> 60787500 | G13: =SUM(G9:G12) -> 92491667 | H13: =SUM(H9:H12) -> 1.3008333e+08 | I13: =SUM(I9:I12) -> 173125000 | J13: =SUM(J9:J12) -> 1.6016667e+08 | ... N13: =SUM(N9:N12) -> 66733333
A14: TOTAL ASSETS | B14: USD | C14: =C6+C13 -> 29200000 | D14: =D6+D13 -> 33708899 | E14: =E6+E13 -> 56323870 | F14: =F6+F13 -> 90991625 | G14: =G6+G13 -> 1.3783617e+08 | H14: =H6+H13 -> 1.9698465e+08 | I14: =I6+I13 -> 2.687162e+08 | J14: =J6+J13 -> 2.9277778e+08 | ... N14: =N6+N13 -> 3.688812e+08
A16: LIABILITIES
A17: EQUITY | B17: USD | C17: ='SOURCE_USE OF FUNDS'!C6 -> 33000000 | D17: ='SOURCE_USE OF FUNDS'!D6 -> 68700000 | E17: ='SOURCE_USE OF FUNDS'!E6 -> 106800000 | F17: ='SOURCE_USE OF FUNDS'!F6 -> 157900000 | G17: ='SOURCE_USE OF FUNDS'!G6 -> 219200000 | H17: ='SOURCE_USE OF FUNDS'!H6 -> 287400000 | I17: ='SOURCE_USE OF FUNDS'!I6 -> 304700000 | J17: ='SOURCE_USE OF FUNDS'!J6 -> 307500000 | ... N17: ='SOURCE_USE OF FUNDS'!N6 -> 307500000
A18: RETAINED EARNINGS | B18: USD | C18: =C14-C17 -> -3800000 | D18: =D14-D17 -> -34991101 | E18: =E14-E17 -> -50476130 | F18: =F14-F17 -> -66908375 | G18: =G14-G17 -> -81363830 | H18: =H14-H17 -> -90415345 | I18: =I14-I17 -> -35983803 | J18: =J14-J17 -> -14722218 | ... N18: =N14-N17 -> 61381201
A19: TOTAL EQUITY | C19: =C17+C18 -> 29200000 | D19: =D17+D18 -> 33708899 | E19: =E17+E18 -> 56323870 | F19: =F17+F18 -> 90991625 | G19: =G17+G18 -> 1.3783617e+08 | H19: =H17+H18 -> 1.9698465e+08 | I19: =I17+I18 -> 2.687162e+08 | J19: =J17+J18 -> 2.9277778e+08 | ... N19: =N17+N18 -> 3.688812e+08
A20: TOTAL LIABILITIES | C20: =C19 -> 29200000 | D20: =D19 -> 33708899 | E20: =E19 -> 56323870 | F20: =F19 -> 90991625 | G20: =G19 -> 1.3783617e+08 | H20: =H19 -> 1.9698465e+08 | I20: =I19 -> 2.687162e+08 | J20: =J19 -> 2.9277778e+08 | ... N20: =N19 -> 3.688812e+08

Sheet SOURCE_USE OF FUNDS
A1: A2 - E CHARGING - SOURCES & USE OF FUNDS
A3: DESCRIPTION | B3: UNIT | C3: CY-2026 | D3: CY-2027 | E3: CY-2028 | F3: CY-2029 | G3: CY-2030 | H3: CY-2031 | I3: CY-2032 | J3: CY-2033 | K3: CY-2034 | L3: CY-2035 | M3: CY-2036 | N3: CY-2037
A4: SOURCE OF FUNDS:
A5: EQUITY-INVESTOR SUBSCRIPTION (25%) | B5: USD | C5: ='ASSUMPTIONS_DATA'!D38-'ASSUMPTIONS_DATA'!D33-'ASSUMPTIONS_DATA'!D32+'ASSUMPTIONS_DATA'!C37 -> 33000000 | D5: ='ASSUMPTIONS_DATA'!E38-'ASSUMPTIONS_DATA'!E33-'ASSUMPTIONS_DATA'!E32 -> 35700000 | E5: ='ASSUMPTIONS_DATA'!F38-'ASSUMPTIONS_DATA'!F33-'ASSUMPTIONS_DATA'!F32 -> 38100000 | F5: ='ASSUMPTIONS_DATA'!G38-'ASSUMPTIONS_DATA'!G33-'ASSUMPTIONS_DATA'!G32 -> 51100000 | G5: ='ASSUMPTIONS_DATA'!H38-'ASSUMPTIONS_DATA'!H33-'ASSUMPTIONS_DATA'!H32 -> 61300000 | H5: ='ASSUMPTIONS_DATA'!I38-'ASSUMPTIONS_DATA'!I33-'ASSUMPTIONS_DATA'!I32 -> 68200000 | I5: ='ASSUMPTIONS_DATA'!J38-'ASSUMPTIONS_DATA'!J33-'ASSUMPTIONS_DATA'!J32 -> 17300000 | J5: ='ASSUMPTIONS_DATA'!K38-'ASSUMPTIONS_DATA'!K33-'ASSUMPTIONS_DATA'!K32 -> 2800000 | K5: ='ASSUMPTIONS_DATA'!L38-'ASSUMPTIONS_DATA'!L33-'ASSUMPTIONS_DATA'!L32 -> 0 | ... M5: ='ASSUMPTIONS_DATA'!N38-'ASSUMPTIONS_DATA'!N33-'ASSUMPTIONS_DATA'!N32 -> 0 | N5: 0
A6: CHANGE IN EQUITY | B6: USD | C6: =C5 -> 33000000 | D6: =D5+C6 -> 68700000 | E6: =E5+D6 -> 106800000 | F6: =F5+E6 -> 157900000 | G6: =G5+F6 -> 219200000 | H6: =H5+G6 -> 287400000 | I6: =I5+H6 -> 304700000 | J6: =J5+I6 -> 307500000 | K6: =K5+J6 -> 307500000 | ... N6: =N5+M6 -> 307500000
A8: USE OF FUNDS:
A9: CHARGING/SWAPPING STATIONS | B9: USD | C9: ='CAPEX & DEPRECIATION'!E3 -> 7000000 | D9: ='CAPEX & DEPRECIATION'!F3 -> 7000000 | E9: ='CAPEX & DEPRECIATION'!G3 -> 7000000 | F9: ='CAPEX & DEPRECIATION'!H3 -> 7000000 | G9: ='CAPEX & DEPRECIATION'!I3 -> 7000000 | H9: ='CAPEX & DEPRECIATION'!J3 -> 7000000 | I9: ='CAPEX & DEPRECIATION'!K3 -> 7000000 | J9: ='CAPEX & DEPRECIATION'!L3 -> 0 | ... N9: ='CAPEX & DEPRECIATION'!P3 -> 0
A10: CHARGERS | B10: USD | C10: ='CAPEX & DEPRECIATION'!E4 -> 10200000 | D10: ='CAPEX & DEPRECIATION'!F4 -> 20400000 | E10: ='CAPEX & DEPRECIATION'!G4 -> 30600000 | F10: ='CAPEX & DEPRECIATION'!H4 -> 40800000 | G10: ='CAPEX & DEPRECIATION'!I4 -> 51000000 | H10: ='CAPEX & DEPRECIATION'!J4 -> 61200000 | I10: ='CAPEX & DEPRECIATION'!K4 -> 10300000 | J10: ='CAPEX & DEPRECIATION'!L4 -> 0 | ... N10: ='CAPEX & DEPRECIATION'!P4 -> 0
A11: SWAPPING BAYS | B11: USD | C11: ='CAPEX & DEPRECIATION'!E5 -> 2800000 | D11: ='CAPEX & DEPRECIATION'!F5 -> 2800000 | E11: ='CAPEX & DEPRECIATION'!G5 -> 0 | F11: ='CAPEX & DEPRECIATION'!H5 -> 2800000 | G11: ='CAPEX & DEPRECIATION'!I5 -> 2800000 | H11: ='CAPEX & DEPRECIATION'!J5 -> 0 | I11: ='CAPEX & DEPRECIATION'!K5 -> 0 | J11: ='CAPEX & DEPRECIATION'!L5 -> 2800000 | ... N11: ='CAPEX & DEPRECIATION'!P5 -> 0
A12: SOFTWARE & PLATFORM DEVELOPMENT | B12: USD | C12: ='CAPEX & DEPRECIATION'!E6 -> 1000000 | D12: ='CAPEX & DEPRECIATION'!F6 -> 500000 | E12: ='CAPEX & DEPRECIATION'!G6 -> 500000 | F12: ='CAPEX & DEPRECIATION'!H6 -> 500000 | G12: ='CAPEX & DEPRECIATION'!I6 -> 500000 | H12: ='CAPEX & DEPRECIATION'!J6 -> 0 | I12: ='CAPEX & DEPRECIATION'!K6 -> 0 | J12: ='CAPEX & DEPRECIATION'!L6 -> 0 | ... N12: ='CAPEX & DEPRECIATION'!P6 -> 0
A13: HARDWARE & OFFICE EQUIPMENT | B13: USD | C13: ='CAPEX & DEPRECIATION'!E7 -> 2000000 | D13: ='CAPEX & DEPRECIATION'!F7 -> 0 | E13: ='CAPEX & DEPRECIATION'!G7 -> 0 | F13: ='CAPEX & DEPRECIATION'!H7 -> 0 | G13: ='CAPEX & DEPRECIATION'!I7 -> 0 | H13: ='CAPEX & DEPRECIATION'!J7 -> 0 | I13: ='CAPEX & DEPRECIATION'!K7 -> 0 | J13: ='CAPEX & DEPRECIATION'!L7 -> 0 | ... N13: ='CAPEX & DEPRECIATION'!P7 -> 0
A14: ='ASSUMPTIONS_DATA'!A36 -> OPERATING RESERVE ( 10% OF FUNDS) | B14: USD | C14: ='ASSUMPTIONS_DATA'!D36 -> 5000000 | D14: ='ASSUMPTIONS_DATA'!E36 -> 5000000 | E14: ='ASSUMPTIONS_DATA'!F36 -> 0 | F14: ='ASSUMPTIONS_DATA'!G36 -> 0 | G14: ='ASSUMPTIONS_DATA'!H36 -> 0 | H14: ='ASSUMPTIONS_DATA'!I36 -> 0 | I14: ='ASSUMPTIONS_DATA'!J36 -> 0 | J14: ='ASSUMPTIONS_DATA'!K36 -> 0 | ... M14: ='ASSUMPTIONS_DATA'!N36 -> 0 | N14: 0
A15: CONTINGENCY RESERVE | B15: USD | C15: ='ASSUMPTIONS_DATA'!C37 -> 5000000 | D15: 0 | E15: 0 | F15: 0 | G15: 0 | H15: 0 | I15: 0 | J15: 0 | K15: 0 | L15: 0 | M15: 0 | N15: 0
A16: TOTAL - USE OF FUNDS | B16: USD | C16: =SUM(C9:C15) -> 33000000 | D16: =SUM(D9:D15) -> 35700000 | E16: =SUM(E9:E15) -> 38100000 | F16: =SUM(F9:F15) -> 51100000 | G16: =SUM(G9:G15) -> 61300000 | H16: =SUM(H9:H15) -> 68200000 | I16: =SUM(I9:I15) -> 17300000 | J16: =SUM(J9:J15) -> 2800000 | ... N16: =SUM(N9:N15) -> 0

Sheet VALUATION SUMMARY
A1: A2 - E CHARGING & BATTERY SWAPPING - REVENUE PROJECTION
A2: METRIC | B2: UNIT | C2: CY-2028 | D2: CY-2030 | E2: CY-2033 | F2: CY-2035 | G2: CY-2036 | H2: CY-2037
A3: EBITDA | B3: USD | C3: ='INCOME STATEMENT '!E12 -> 5730791.5 | D3: ='INCOME STATEMENT '!G12 -> 17156612 | E3: ='INCOME STATEMENT '!J12 -> 42437740 | F3: ='INCOME STATEMENT '!L12 -> 48869337 | G3: ='INCOME STATEMENT '!M12 -> 52266326 | H3: ='INCOME STATEMENT '!N12 -> 54208112
A4: VALUATION MULTIPLE | C4: 10 | D4: 12 | E4: 12 | F4: 12 | G4: 12 | H4: 12
A5: ENTERPRISE VALUE | B5: USD | C5: =C3*C4 -> 57307915 | D5: =D3*D4 -> 2.0587934e+08 | E5: =E3*E4 -> 5.0925289e+08 | F5: =F3*F4 -> 5.8643204e+08 | G5: =G3*G4 -> 6.2719591e+08 | H5: =H3*H4 -> 6.5049735e+08
A6: LESS: NET DEBT | B6: USD | C6: 0 | D6: 0 | E6: 0 | F6: 0 | G6: 0 | H6: 0
A7: EQUITY VALUE | B7: USD | C7: =C5-C6 -> 57307915 | D7: =D5-D6 -> 2.0587934e+08 | E7: =E5-E6 -> 5.0925289e+08 | F7: =F5-F6 -> 5.8643204e+08 | G7: =G5-G6 -> 6.2719591e+08 | H7: =H5-H6 -> 6.5049735e+08
A8: INVESTOR 25% STAKE VALUE | B8: USD | C8: =C7*0.25 -> 14326979 | D8: =D7*0.25 -> 51469835 | E8: =E7*0.25 -> 1.2731322e+08 | F8: =F7*0.25 -> 1.4660801e+08 | G8: =G7*0.25 -> 1.5679898e+08 | H8: =H7*0.25 -> 1.6262434e+08
A9: MOIC | C9: =C8/'SOURCE_USE OF FUNDS'!$C$5 -> 0.43415087 | D9: =D8/'SOURCE_USE OF FUNDS'!$C$5 -> 1.559692 | E9: =E8/'SOURCE_USE OF FUNDS'!$C$5 -> 3.8579764 | F9: =F8/'SOURCE_USE OF FUNDS'!$C$5 -> 4.442667 | G9: =G8/'SOURCE_USE OF FUNDS'!$C$5 -> 4.7514841 | H9: =H8/'SOURCE_USE OF FUNDS'!$C$5 -> 4.9280102
A11: IRR | B11: % | G11: ='INCOME STATEMENT '!C24 -> 0.16517774

Sheet KEY METRICS
A1: A2 - E CHARGING & BATTERY SWAPPING - REVENUE PROJECTION
A2: DESCRIPTION | B2: UNIT | C2: CY-2027 | D2: CY-2028 | E2: CY-2029 | F2: CY-2030 | G2: CY-2031 | H2: CY-2032 | I2: CY-2033 | J2: CY-2034 | K2: CY-2035 | L2: CY-2036 | M2: CY-2037
A3: EBITDA MARGIN | B3: % | C3: ='INCOME STATEMENT '!D12/'INCOME STATEMENT '!D3 -> 0.081689193 | D3: ='INCOME STATEMENT '!E12/'INCOME STATEMENT '!E3 -> 0.16791915 | E3: ='INCOME STATEMENT '!F12/'INCOME STATEMENT '!F3 -> 0.19516608 | F3: ='INCOME STATEMENT '!G12/'INCOME STATEMENT '!G3 -> 0.20773122 | G3: ='INCOME STATEMENT '!H12/'INCOME STATEMENT '!H3 -> 0.21446235 | H3: ='INCOME STATEMENT '!I12/'INCOME STATEMENT '!I3 -> 0.21829911 | I3: ='INCOME STATEMENT '!J12/'INCOME STATEMENT '!J3 -> 0.22051221 | J3: ='INCOME STATEMENT '!K12/'INCOME STATEMENT '!K3 -> 0.21533594 | ... M3: ='INCOME STATEMENT '!N12/'INCOME STATEMENT '!N3 -> 0.19238621
A4: NET MARGIN | B4: % | C4: ='INCOME STATEMENT '!D17/'INCOME STATEMENT '!D3 -> -0.049707218 | D4: ='INCOME STATEMENT '!E17/'INCOME STATEMENT '!E3 -> 0.033842045 | E4: ='INCOME STATEMENT '!F17/'INCOME STATEMENT '!F3 -> 0.053412648 | F4: ='INCOME STATEMENT '!G17/'INCOME STATEMENT '!G3 -> 0.056962344 | G4: ='INCOME STATEMENT '!H17/'INCOME STATEMENT '!H3 -> 0.057488368 | H4: ='INCOME STATEMENT '!I17/'INCOME STATEMENT '!I3 -> 0.062784787 | I4: ='INCOME STATEMENT '!J17/'INCOME STATEMENT '!J3 -> 0.065687377 | J4: ='INCOME STATEMENT '!K17/'INCOME STATEMENT '!K3 -> 0.068289822 | ... M4: ='INCOME STATEMENT '!N17/'INCOME STATEMENT '!N3 -> 0.070468478
A5: ROE | B5: % | C5: ='INCOME STATEMENT '!D17/'BALANCE SHEET'!D17 -> -0.011224175 | D5: ='INCOME STATEMENT '!E17/'BALANCE SHEET'!E17 -> 0.010814333 | E5: ='INCOME STATEMENT '!F17/'BALANCE SHEET'!F17 -> 0.019048479 | F5: ='INCOME STATEMENT '!G17/'BALANCE SHEET'!G17 -> 0.021462339 | G5: ='INCOME STATEMENT '!H17/'BALANCE SHEET'!H17 -> 0.022715676 | H5: ='INCOME STATEMENT '!I17/'BALANCE SHEET'!I17 -> 0.030887898 | I5: ='INCOME STATEMENT '!J17/'BALANCE SHEET'!J17 -> 0.041110845 | J5: ='INCOME STATEMENT '!K17/'BALANCE SHEET'!K17 -> 0.047013562 | ... L5: ='INCOME STATEMENT '!M17/'BALANCE SHEET'!M17 -> 0.062010877

Sheet ASSUMPTIONS_DATA
A1: A2 - E BATTERY SWAPPING / FLEET OPERATIONS - ASSUMPTIONS/DATA
A2: DESCRIPTION | B2: UNIT | C2: QUANTITY | D2: CY-2027 | E2: CY-2028 | F2: CY-2029 | G2: CY-2030 | H2: CY-2031 | I2: CY-2032 | J2: CY-2033 | K2: CY-2034 | L2: CY-2035 | M2: CY-2036 | N2: CY-2037
A3: MAXIMUM DISTANCE BETWEEN CHARGING STATIONS | B3: KMS | C3: 220
A4: NUMBER OF STATIONS | B4: NUMBER | C4: 7 | D4: 7 | E4: 7 | F4: 7 | G4: 7 | H4: 7 | I4: 7 | J4: 7 | K4: 7 | L4: 7 | M4: 7 | N4: 7
A5: NUMBER OF TRUCKS ADDED | B5: NUMBER | D5: 714 | E5: 714 | F5: 714 | G5: 714 | H5: 714 | I5: 714 | J5: 716
A6: NUMBER OF TRUCKS CUMALATIVE | B6: NUMBER | D6: =D5 -> 714 | E6: =D6+E5 -> 1428 | F6: =E6+F5 -> 2142 | G6: =F6+G5 -> 2856 | H6: =G6+H5 -> 3570 | I6: =H6+I5 -> 4284 | J6: =I6+J5 -> 5000 | K6: =J6+K5 -> 5000 | L6: =K6+L5 -> 5000 | ... N6: =M6+N5 -> 5000
A7: NUMBER OF SWAPS PER TRUCK PER DAY | B7: NUMBER | C7: 1 | D7: 1 | E7: 1 | F7: 1 | G7: 1 | H7: 1 | I7: 1 | J7: 1 | K7: 1 | L7: 1 | M7: 1 | N7: 1
A8: NUMBER OF TOTAL SWAPS PER DAY | B8: NUMBER | D8: =D6*D7 -> 714 | E8: =E6*E7 -> 1428 | F8: =F6*F7 -> 2142 | G8: =G6*G7 -> 2856 | H8: =H6*H7 -> 3570 | I8: =I6*I7 -> 4284 | J8: =J6*J7 -> 5000 | K8: =K6*K7 -> 5000 | ... N8: =N6*N7 -> 5000
A9: NUMBER OF MINUTES PER SWAP | B9: MINUTES | C9: 7
A10: NUMBER OF SWAPS PER HOUR | B10: NUMBER | C10: =60/C9 -> 8.5714286
A11: NUMBER OF HOURS OF SWAPPING PER DAY | B11: HOURS | C11: 18
A12: NUMBER OF SWAPS PER SWAPPING BAY PER DAY | B12: NUMBER | C12: =C11*C10 -> 154.28571
A13: NUMBER OF BATTERY PACKS TO SWAP PER DAY | B13: NUMBER | D13: =D6 -> 714 | E13: =E6 -> 1428 | F13: =F6 -> 2142 | G13: =G6 -> 2856 | H13: =H6 -> 3570 | I13: =I6 -> 4284 | J13: =J6 -> 5000 | K13: =K6 -> 5000 | ... N13: =N6 -> 5000
A14: NUMBER OF HOURS/DAY OF CHARGING PER CHARGER | B14: NUMBER | C14: 7
A15: NUMBER OF BATTERY PACKS CHARGED PER CHARGER PER DAY | B15: NUMBER | C15: 7
A16: NUMBER OF CHARGERS REQUIRED | B16: NUMBER | D16: =D13/$C$15 -> 102 | E16: =E13/$C$15 -> 204 | F16: =F13/$C$15 -> 306 | G16: =G13/$C$15 -> 408 | H16: =H13/$C$15 -> 510 | I16: =I13/$C$15 -> 612 | J16: 103
A17: NUMBER OF CHARGERS PER STATION | B17: NUMBER | D17: =D16/$C$4 -> 14.571429 | E17: =E16/$C$4 -> 29.142857 | F17: =F16/$C$4 -> 43.714286 | G17: =G16/$C$4 -> 58.285714 | H17: =H16/$C$4 -> 72.857143 | I17: =I16/$C$4 -> 87.428571 | J17: =J16/$C$4 -> 14.714286
A18: NUMBER OF SWAPPING BAYS PER STATION | B18: NUMBER | D18: 7 | E18: 14 | F18: 14 | G18: 21 | H18: 28 | I18: 28 | J18: 28 | K18: 35 | L18: 35 | M18: 35 | N18: 35
A19: NUMBER OF BATTERY PACKS PER TRUCK | B19: NUMBER | C19: 1.5
A20: NUMBER OF BATTERY PACKS REQUIRED | B20: NUMBER | D20: =D5*$C$19 -> 1071 | E20: =E5*$C$19 -> 1071 | F20: =F5*$C$19 -> 1071 | G20: =G5*$C$19 -> 1071 | H20: =H5*$C$19 -> 1071 | I20: =I5*$C$19 -> 1071 | J20: =J5*$C$19 -> 1074
A21: BATTERY PACK REPLACEMENT | B21: NUMBER | C21: 0 | D21: 0 | E21: 0 | F21: 0 | G21: 0 | H21: 0 | I21: 0 | J21: 0 | K21: 0 | L21: 0 | M21: =D20 -> 1071 | N21: =E20 -> 1071
A22: TOTAL NUMBER OF BATTERY PACKS | B22: NUMBER | C22: =C21+C20 -> 0 | D22: =D21+D20 -> 1071 | E22: =E21+E20+D22 -> 2142 | F22: =F21+F20+E22 -> 3213 | G22: =G21+G20+F22 -> 4284 | H22: =H21+H20+G22 -> 5355 | I22: =I21+I20+H22 -> 6426 | J22: =J21+J20+I22 -> 7500 | K22: =K21+K20+J22 -> 7500 | L22: =L21+L20+K22 -> 7500 | M22: =L22 -> 7500 | N22: =M22 -> 7500
A24: COST PER CHARGING/SWAPPING STATION | B24: USD | C24: 1000000
A25: COST PER CHARGER | B25: USD | C25: 100000
A26: COST OF SWAPPING BAY | B26: USD | C26: 400000
A27: COST PER BATTERY PACK | B27: USD | C27: 65000
A28: COST PER TRUCK | B28: USD | C28: 70000
A29: TOTAL COST OF CHARGING/SWAPPING STATIONS | B29: USD | C29: =$C$24*C4 -> 7000000 | D29: =$C$24*D4 -> 7000000 | E29: =$C$24*E4 -> 7000000 | F29: =$C$24*F4 -> 7000000 | G29: =$C$24*G4 -> 7000000 | H29: =$C$24*H4 -> 7000000 | I29: =$C$24*I4 -> 7000000 | J29: =$C$24*J4 -> 7000000
A30: TOTAL COST OF CHARGERS | B30: USD | C30: =$C$25*C16 -> 0 | D30: =$C$25*D16 -> 10200000 | E30: =$C$25*E16 -> 20400000 | F30: =$C$25*F16 -> 30600000 | G30: =$C$25*G16 -> 40800000 | H30: =$C$25*H16 -> 51000000 | I30: =$C$25*I16 -> 61200000 | J30: =$C$25*J16 -> 10300000
A31: TOTAL COST OF SWAPPING BAYS | B31: USD | D31: =$C$26*(D18) -> 2800000 | E31: =$C$26*(E18-D18) -> 2800000 | F31: =$C$26*(F18-E18) -> 0 | G31: =$C$26*(G18-F18) -> 2800000 | H31: =$C$26*(H18-G18) -> 2800000 | I31: =$C$26*(I18-H18) -> 0 | J31: =$C$26*(J18-I18) -> 0 | K31: =$C$26*(K18-J18) -> 2800000 | L31: =$C$26*(L18-K18) -> 0 | ... N31: =$C$26*(N18-M18) -> 0
A32: TOTAL COST OF BATTERY PACKS | B32: USD | C32: =$C$27*C22 -> 0 | D32: =$C$27*D20 -> 69615000 | E32: =$C$27*E20 -> 69615000 | F32: =$C$27*F20 -> 69615000 | G32: =$C$27*G20 -> 69615000 | H32: =$C$27*H20 -> 69615000 | I32: =$C$27*I20 -> 69615000 | J32: =$C$27*J20 -> 69810000 | K32: =$C$27*K20 -> 0 | L32: =$C$27*L20 -> 0 | M32: =$C$27*M21 -> 69615000 | N32: =$C$27*N21 -> 69615000
A33: TOTAL COST OF TRUCKS | B33: USD | C33: =$C$28*C5 -> 0 | D33: =$C$28*D5 -> 49980000 | E33: =$C$28*E5 -> 49980000 | F33: =$C$28*F5 -> 49980000 | G33: =$C$28*G5 -> 49980000 | H33: =$C$28*H5 -> 49980000 | I33: =$C$28*I5 -> 49980000 | J33: =$C$28*J5 -> 50120000
A34: SOFTWARE & PLATFORM DEVELOPMENT | B34: USD | C34: =SUM(D34:J34) -> 3000000 | D34: 1000000 | E34: 500000 | F34: 500000 | G34: 500000 | H34: 500000
A35: HARDWARE & OFFICE EQUIPMENT | B35: USD | C35: 2000000 | D35: =C35 -> 2000000
A36: OPERATING RESERVE ( 10% OF FUNDS) | B36: USD | C36: 10000000 | D36: =$C$36/2 -> 5000000 | E36: =$C$36/2 -> 5000000
A37: CONTINGENCY RESERVE | B37: USD | C37: 5000000
A38: TOTAL INVESTMENT | B38: USD | C38: =SUM(D38:J38) -> 1137200000 | D38: =SUM(D29:D37) -> 147595000 | E38: =SUM(E29:E37) -> 155295000 | F38: =SUM(F29:F37) -> 157695000 | G38: =SUM(G29:G37) -> 170695000 | H38: =SUM(H29:H37) -> 180895000 | I38: =SUM(I29:I37) -> 187795000 | J38: =SUM(J29:J37) -> 137230000 | K38: =SUM(K29:K37) -> 2800000 | ... N38: =SUM(N29:N37) -> 69615000

Sheet POWER CALCULATIONS
A1: A2 - E BATTERY SWAPPING / FLEET OPERATIONS -POWER CALCULATIONS
A2: DESCRIPTION | B2: UNIT | C2: QUANTITY | D2: CY-2027 | E2: CY-2028 | F2: CY-2029 | G2: CY-2030 | H2: CY-2031 | I2: CY-2032 | J2: CY-2033 | K2: CY-2034 | L2: CY-2035 | M2: CY-2036 | N2: CY-2037
A3: NUMBER OF TRUCKS | B3: NUMBER | C3: 5000 | D3: ='ASSUMPTIONS_DATA'!D5 -> 714 | E3: ='ASSUMPTIONS_DATA'!E5+D3 -> 1428 | F3: ='ASSUMPTIONS_DATA'!F5+E3 -> 2142 | G3: ='ASSUMPTIONS_DATA'!G5+F3 -> 2856 | H3: ='ASSUMPTIONS_DATA'!H5+G3 -> 3570 | I3: ='ASSUMPTIONS_DATA'!I5+H3 -> 4284 | J3: ='ASSUMPTIONS_DATA'!J5+I3 -> 5000 | K3: ='ASSUMPTIONS_DATA'!K5+J3 -> 5000 | L3: ='ASSUMPTIONS_DATA'!L5+K3 -> 5000 | ... N3: ='ASSUMPTIONS_DATA'!N5+M3 -> 5000
A4: AVERAGE KILOMETRES PER TRUCK PER YEAR | B4: KM | C4: 60000
A5: TOTAL KILOMETRES OF FLEET | B5: KM | C5: 60000 | D5: =$C$4*D3 -> 42840000 | E5: =$C$4*E3 -> 85680000 | F5: =$C$4*F3 -> 128520000 | G5: =$C$4*G3 -> 171360000 | H5: =$C$4*H3 -> 214200000 | I5: =$C$4*I3 -> 257040000 | J5: =$C$4*J3 -> 300000000 | K5: =$C$4*K3 -> 300000000 | ... N5: =$C$4*N3 -> 300000000
A6: BATTERY CAPACITY PER TRUCK | B6: KWh | C6: 588
A7: RATED RANGE PER CHARGE | B7: KM | C7: 350
A8: REAL USE RANGE PER CHARGE | B8: KM | C8: 220
A9: ENERGY USED PER KM | B9: KWh | C9: =C6/C8 -> 2.6727273
A10: ANNUAL ENERGY USE PER TRUCK | B10: KWh | C10: =C5*C9 -> 160363.64
A11: ANNUAL ENERGY USE PER TRUCK | B11: MWh | C11: =C10/1000 -> 160.36364
A12: TOTAL ENERGY USE FOR FLEET | B12: MWh | D12: =$C$11*D3 -> 114499.64 | E12: =$C$11*E3 -> 228999.27 | F12: =$C$11*F3 -> 343498.91 | G12: =$C$11*G3 -> 457998.55 | H12: =$C$11*H3 -> 572498.18 | I12: =$C$11*I3 -> 686997.82 | J12: =$C$11*J3 -> 801818.18 | K12: =$C$11*K3 -> 801818.18 | ... N12: =$C$11*N3 -> 801818.18
A13: CHARGING TIME PER BATTERY PACK | B13: HOURS | C13: 1
A14: POWER LOAD PER CHARGE | B14: KWh | C14: 588
A15: POWER INPUT PER CHARGE (KWh/h) | B15: KW | C15: =C14/C13 -> 588
A16: COMPENSATION FOR THERMAL AND CHEMICAL CONVERSION LOSS | B16: % | C16: 0.1
A17: AVERAGE RESIDUAL CHARGE | B17: % | C17: 0.2
A18: AVERAGE RESIDUAL CHARGE | B18: KWh | C18: =C14*C17 -> 117.6
A19: ACTUAL CHARGING LOAD | B19: KW | C19: =C14-C18 -> 470.4
A20: NET POWER INPUT PER CHARGE | B20: KW | C20: =C19*1.1 -> 517.44
A21: NUMBER OF HOURS OF CHARGING PER DAY | B21: HOURS | C21: 7
A22: TOTAL POWER PER CHARGER PERDAY | B22: KWh | C22: =C20*C21 -> 3622.08
B23: MWh | C23: =C22/1000 -> 3.62208
A24: NUMBER OF CHARGERS | B24: NUMBER | C24: ='ASSUMPTIONS_DATA'!C16 -> 0 | D24: ='ASSUMPTIONS_DATA'!D16 -> 102 | E24: ='ASSUMPTIONS_DATA'!E16+D24 -> 306 | F24: ='ASSUMPTIONS_DATA'!F16+E24 -> 612 | G24: ='ASSUMPTIONS_DATA'!G16+F24 -> 1020 | H24: ='ASSUMPTIONS_DATA'!H16+G24 -> 1530 | I24: ='ASSUMPTIONS_DATA'!I16+H24 -> 2142 | J24: ='ASSUMPTIONS_DATA'!J16+I24 -> 2245 | K24: ='ASSUMPTIONS_DATA'!K16+J24 -> 2245 | L24: ='ASSUMPTIONS_DATA'!L16+K24 -> 2245 | ... N24: ='ASSUMPTIONS_DATA'!N16+M24 -> 2245
A25: TOTAL POWER PER DAY | B25: MWh | C25: =C24*$C$23 -> 0 | D25: =D24*$C$23 -> 369.45216 | E25: =E24*$C$23 -> 1108.3565 | F25: =F24*$C$23 -> 2216.713 | G25: =G24*$C$23 -> 3694.5216 | H25: =H24*$C$23 -> 5541.7824 | I25: =I24*$C$23 -> 7758.4954 | J25: =J24*$C$23 -> 8131.5696 | ... N25: =N24*$C$23 -> 8131.5696
A26: TOTAL CONNECTED POWER | B26: MW | C26: =C25/$C$21 -> 0 | D26: =D25/$C$21 -> 52.77888 | E26: =E25/$C$21 -> 158.33664 | F26: =F25/$C$21 -> 316.67328 | G26: =G25/$C$21 -> 527.7888 | H26: =H25/$C$21 -> 791.6832 | I26: =I25/$C$21 -> 1108.3565 | J26: =J25/$C$21 -> 1161.6528 | ... N26: =N25/$C$21 -> 1161.6528
A27: TOTAL POWER UNITS CONSUMED PER YEAR | B27: KW | D27: =D5*$C$9 -> 1.1449964e+08 | E27: =E5*$C$9 -> 2.2899927e+08 | F27: =F5*$C$9 -> 3.4349891e+08 | G27: =G5*$C$9 -> 4.5799855e+08 | H27: =H5*$C$9 -> 5.7249818e+08 | I27: =I5*$C$9 -> 6.8699782e+08 | J27: =J5*$C$9 -> 8.0181818e+08 | K27: =K5*$C$9 -> 8.0181818e+08 | ... N27: =N5*$C$9 -> 8.0181818e+08
A28: PURCHASE RATE PER KW | B28: ETB | C28: 7
A29: PURCHASE RATE PER KW | B29: USD | C29: =C28/155 -> 0.04516129 | D29: =C29 -> 0.04516129 | E29: =D29*1.1 -> 0.049677419 | F29: =E29*1.1 -> 0.054645161 | G29: =F29*1.1 -> 0.060109677 | H29: =G29*1.1 -> 0.066120645 | I29: =H29*1.1 -> 0.07273271 | J29: =I29*1.1 -> 0.080005981 | K29: =J29*1.1 -> 0.088006579 | L29: =K29*1.1 -> 0.096807237 | ... N29: =M29*1.1 -> 0.11713676
A30: COST OF POWER | B30: USD | D30: =D27*D29 -> 5170951.3 | E30: =E27*E29 -> 11376093 | F30: =F27*F29 -> 18770553 | G30: =G27*G29 -> 27530145 | H30: =H27*H29 -> 37853949 | I30: =I27*I29 -> 49967213 | J30: =J27*J29 -> 64150250 | K30: =K27*K29 -> 70565275 | ... N30: =N27*N29 -> 93922381

Sheet CAPEX & DEPRECIATION
A1: A2 - E CHARGING & BATTERY SWAPPING- CAPEX & DEPRECIATION
A2: DESCRIPTION | B2: ASSET TYPE | C2: USEFUL LIFE (YEARS) | D2: UNIT | E2: CY-2026 | F2: CY-2027 | G2: CY-2028 | H2: CY-2029 | I2: CY-2030 | J2: CY-2031 | K2: CY-2032 | L2: CY-2033 | M2: CY-2034 | N2: CY-2035 | O2: CY-2036 | P2: CY-2037
A3: CHARGING/SWAPPING STATIONS | B3: CIVIL WORKS, TRANSFORMERS | C3: 12 | D3: USD | E3: ='ASSUMPTIONS_DATA'!D29 -> 7000000 | F3: ='ASSUMPTIONS_DATA'!E29 -> 7000000 | G3: ='ASSUMPTIONS_DATA'!F29 -> 7000000 | H3: ='ASSUMPTIONS_DATA'!G29 -> 7000000 | I3: ='ASSUMPTIONS_DATA'!H29 -> 7000000 | J3: ='ASSUMPTIONS_DATA'!I29 -> 7000000 | K3: ='ASSUMPTIONS_DATA'!J29 -> 7000000 | L3: ='ASSUMPTIONS_DATA'!K29 -> 0 | ... O3: ='ASSUMPTIONS_DATA'!N29 -> 0 | P3: ='ASSUMPTIONS_DATA'!N29 -> 0
A4: CHARGERS | B4: CHARGERS, CONNECTORS, POWER ELECTRONICS | C4: 12 | D4: USD | E4: ='ASSUMPTIONS_DATA'!D30 -> 10200000 | F4: ='ASSUMPTIONS_DATA'!E30 -> 20400000 | G4: ='ASSUMPTIONS_DATA'!F30 -> 30600000 | H4: ='ASSUMPTIONS_DATA'!G30 -> 40800000 | I4: ='ASSUMPTIONS_DATA'!H30 -> 51000000 | J4: ='ASSUMPTIONS_DATA'!I30 -> 61200000 | K4: ='ASSUMPTIONS_DATA'!J30 -> 10300000 | L4: ='ASSUMPTIONS_DATA'!K30 -> 0 | ... O4: ='ASSUMPTIONS_DATA'!N30 -> 0 | P4: ='ASSUMPTIONS_DATA'!N30 -> 0
A5: SWAPPING BAYS | B5: SWAPPING BAYS | C5: 10 | D5: USD | E5: ='ASSUMPTIONS_DATA'!D31 -> 2800000 | F5: ='ASSUMPTIONS_DATA'!E31 -> 2800000 | G5: ='ASSUMPTIONS_DATA'!F31 -> 0 | H5: ='ASSUMPTIONS_DATA'!G31 -> 2800000 | I5: ='ASSUMPTIONS_DATA'!H31 -> 2800000 | J5: ='ASSUMPTIONS_DATA'!I31 -> 0 | K5: ='ASSUMPTIONS_DATA'!J31 -> 0 | L5: ='ASSUMPTIONS_DATA'!K31 -> 2800000 | ... O5: ='ASSUMPTIONS_DATA'!N31 -> 0 | P5: ='ASSUMPTIONS_DATA'!N31 -> 0
A6: SOFTWARE & PLATFORM DEVELOPMENT | C6: 8 | E6: ='ASSUMPTIONS_DATA'!D34 -> 1000000 | F6: ='ASSUMPTIONS_DATA'!E34 -> 500000 | G6: ='ASSUMPTIONS_DATA'!F34 -> 500000 | H6: ='ASSUMPTIONS_DATA'!G34 -> 500000 | I6: ='ASSUMPTIONS_DATA'!H34 -> 500000 | J6: ='ASSUMPTIONS_DATA'!I34 -> 0 | K6: ='ASSUMPTIONS_DATA'!J34 -> 0 | L6: ='ASSUMPTIONS_DATA'!K34 -> 0 | ... O6: ='ASSUMPTIONS_DATA'!N34 -> 0 | P6: ='ASSUMPTIONS_DATA'!N33 -> 0
A7: HARDWARE & OFFICE EQUIPMENT | B7: DATA CENTRE, ADMIN OFFICE | C7: 10 | E7: ='ASSUMPTIONS_DATA'!D35 -> 2000000 | F7: ='ASSUMPTIONS_DATA'!E35 -> 0 | G7: ='ASSUMPTIONS_DATA'!F35 -> 0 | H7: ='ASSUMPTIONS_DATA'!G35 -> 0 | I7: ='ASSUMPTIONS_DATA'!H35 -> 0 | J7: ='ASSUMPTIONS_DATA'!I35 -> 0 | K7: ='ASSUMPTIONS_DATA'!J35 -> 0 | L7: ='ASSUMPTIONS_DATA'!K35 -> 0 | ... O7: ='ASSUMPTIONS_DATA'!N35 -> 0 | P7: ='ASSUMPTIONS_DATA'!N34 -> 0
A8: TOTAL-CAPEX | D8: USD | E8: =SUM(E3:E7) -> 23000000 | F8: =SUM(F3:F7) -> 30700000 | G8: =SUM(G3:G7) -> 38100000 | H8: =SUM(H3:H7) -> 51100000 | I8: =SUM(I3:I7) -> 61300000 | J8: =SUM(J3:J7) -> 68200000 | K8: =SUM(K3:K7) -> 17300000 | L8: =SUM(L3:L7) -> 2800000 | ... P8: =SUM(P3:P7) -> 0
A10: LESS: DEPRECIATION | D10: USD | E10: 0 | F10: =F45 -> 2038333.3 | G10: =G45 -> 4080833.3 | H10: =H45 -> 6693333.3 | I10: =I45 -> 10435833 | J10: =J45 -> 15028333 | K10: =K45 -> 19278333 | L10: =L45 -> 24378333 | M10: =M45 -> 24933333 | ... P10: =P45 -> 24545833
A11: CAPEX - CLOSING BALANCE | D11: USD | E11: =E8-E10 -> 23000000 | F11: =F8-F10 -> 28661667 | G11: =G8-G10 -> 34019167 | H11: =H8-H10 -> 44406667 | I11: =I8-I10 -> 50864167 | J11: =J8-J10 -> 53171667 | K11: =K8-K10 -> -1978333.3 | L11: =L8-L10 -> -21578333 | ... P11: =P8-P10 -> -24545833
A14: DEPRECIATION GRID
A15: DESCRIPTION | B15: YEAR OF ADDITION | C15: USEFUL LIFE (YEARS) | D15: UNIT | E15: CY-2026 | F15: CY-2027 | G15: CY-2028 | H15: CY-2029 | I15: CY-2030 | J15: CY-2031 | K15: CY-2032 | L15: CY-2033 | M15: CY-2034 | N15: CY-2035 | O15: CY-2036
A16: CHARGING/SWAPPING STATIONS | B16: =E15 -> CY-2026 | C16: =C3 -> 12 | D16: USD | F16: =$E$3/$C$3 -> 583333.33 | G16: =$E$3/$C$3 -> 583333.33 | H16: =$E$3/$C$3 -> 583333.33 | I16: =$E$3/$C$3 -> 583333.33 | J16: =$E$3/$C$3 -> 583333.33 | K16: =$E$3/$C$3 -> 583333.33 | L16: =$E$3/$C$3 -> 583333.33
A17: CHARGERS | B17: =E15 -> CY-2026 | C17: =$C$4 -> 12 | D17: USD | F17: =$E$4/$C$4 -> 850000 | G17: =$E$4/$C$4 -> 850000 | H17: =$E$4/$C$4 -> 850000 | I17: =$E$4/$C$4 -> 850000 | J17: =$E$4/$C$4 -> 850000
A18: ADDITION 1 | B18: =F15 -> CY-2027 | C18: =$C$4 -> 12 | D18: USD | G18: =$F$4/$C$18 -> 1700000 | H18: =$F$4/$C$18 -> 1700000 | I18: =$F$4/$C$18 -> 1700000 | J18: =$F$4/$C$18 -> 1700000 | K18: =$F$4/$C$18 -> 1700000 | L18: =$F$4/$C$18 -> 1700000 | M18: =$F$4/$C$18 -> 1700000 | N18: =$F$4/$C$18 -> 1700000 | ... P18: =$F$4/$C$18 -> 1700000
A19: ADDITION 2 | B19: =G15 -> CY-2028 | C19: =$C$4 -> 12 | D19: USD | H19: =$G$4/$C$18 -> 2550000 | I19: =$G$4/$C$18 -> 2550000 | J19: =$G$4/$C$18 -> 2550000 | K19: =$G$4/$C$18 -> 2550000 | L19: =$G$4/$C$18 -> 2550000 | M19: =$G$4/$C$18 -> 2550000 | N19: =$G$4/$C$18 -> 2550000 | O19: =$G$4/$C$18 -> 2550000 | P19: =$G$4/$C$18 -> 2550000
A20: ADDITION 3 | B20: =H15 -> CY-2029 | C20: =$C$4 -> 12 | D20: USD | I20: =$H$4/$C$18 -> 3400000 | J20: =$H$4/$C$18 -> 3400000 | K20: =$H$4/$C$18 -> 3400000 | L20: =$H$4/$C$18 -> 3400000 | M20: =$H$4/$C$18 -> 3400000 | N20: =$H$4/$C$18 -> 3400000 | O20: =$H$4/$C$18 -> 3400000 | P20: =$H$4/$C$18 -> 3400000
A21: ADDITION 4 | B21: =I15 -> CY-2030 | C21: =$C$4 -> 12 | D21: USD | J21: =$I$4/$C$18 -> 4250000 | K21: =$I$4/$C$18 -> 4250000 | L21: =$I$4/$C$18 -> 4250000 | M21: =$I$4/$C$18 -> 4250000 | N21: =$I$4/$C$18 -> 4250000 | O21: =$I$4/$C$18 -> 4250000 | P21: =$I$4/$C$18 -> 4250000
A22: ADDITION 5 | B22: =J15 -> CY-2031 | C22: =$C$4 -> 12 | D22: USD | K22: =$J$4/$C$18 -> 5100000 | L22: =$J$4/$C$18 -> 5100000 | M22: =$J$4/$C$18 -> 5100000 | N22: =$J$4/$C$18 -> 5100000 | O22: =$J$4/$C$18 -> 5100000 | P22: =$J$4/$C$18 -> 5100000
A23: ADDITION 6 | B23: =K15 -> CY-2032 | C23: =$C$4 -> 12 | D23: USD | L23: =$J$4/$C$18 -> 5100000 | M23: =$J$4/$C$18 -> 5100000 | N23: =$J$4/$C$18 -> 5100000 | O23: =$J$4/$C$18 -> 5100000 | P23: =$J$4/$C$18 -> 5100000
A24: ADDITION 7 | B24: =L15 -> CY-2033 | C24: =$C$4 -> 12 | D24: USD | M24: =$K$4/$C$18 -> 858333.33 | N24: =$K$4/$C$18 -> 858333.33 | O24: =$K$4/$C$18 -> 858333.33 | P24: =$K$4/$C$18 -> 858333.33
A25: TOTAL | F25: =SUM(F17:F24) -> 850000 | G25: =SUM(G17:G24) -> 2550000 | H25: =SUM(H17:H24) -> 5100000 | I25: =SUM(I17:I24) -> 8500000 | J25: =SUM(J17:J24) -> 12750000 | K25: =SUM(K17:K24) -> 17000000 | L25: =SUM(L17:L24) -> 22100000 | M25: =SUM(M17:M24) -> 22958333 | ... P25: =SUM(P17:P24) -> 22958333
A26: SWAPPING BAYS | B26: CY-2026 | C26: =$C$5 -> 10 | D26: USD | F26: =$E$5/$C$5 -> 280000 | G26: =$E$5/$C$5 -> 280000 | H26: =$E$5/$C$5 -> 280000 | I26: =$E$5/$C$5 -> 280000 | J26: =$E$5/$C$5 -> 280000 | K26: =$E$5/$C$5 -> 280000 | L26: =$E$5/$C$5 -> 280000 | M26: =$E$5/$C$5 -> 280000 | ... P26: =$E$5/$C$5 -> 280000
A27: ADDITION 1 | B27: CY-2027 | C27: =$C$5 -> 10 | D27: USD | G27: =$F$5/$C$27 -> 280000 | H27: =$F$5/$C$27 -> 280000 | I27: =$F$5/$C$27 -> 280000 | J27: =$F$5/$C$27 -> 280000 | K27: =$F$5/$C$27 -> 280000 | L27: =$F$5/$C$27 -> 280000 | M27: =$F$5/$C$27 -> 280000 | N27: =$F$5/$C$27 -> 280000 | ... P27: =$F$5/$C$27 -> 280000
A28: ADDITION 2 | B28: CY-2028 | C28: =$C$5 -> 10 | D28: USD | H28: =$G$5/$C$27 -> 0 | I28: =$G$5/$C$27 -> 0 | J28: =$G$5/$C$27 -> 0 | K28: =$G$5/$C$27 -> 0 | L28: =$G$5/$C$27 -> 0 | M28: =$G$5/$C$27 -> 0 | N28: =$G$5/$C$27 -> 0 | O28: =$G$5/$C$27 -> 0 | P28: =$G$5/$C$27 -> 0
A29: ADDITION 3 | B29: CY-2029 | C29: =$C$5 -> 10 | D29: USD | I29: =$H$5/$C$27 -> 280000 | J29: =$H$5/$C$27 -> 280000 | K29: =$H$5/$C$27 -> 280000 | L29: =$H$5/$C$27 -> 280000 | M29: =$H$5/$C$27 -> 280000 | N29: =$H$5/$C$27 -> 280000 | O29: =$H$5/$C$27 -> 280000 | P29: =$H$5/$C$27 -> 280000
A30: ADDITION 4 | B30: CY-2030 | C30: =$C$5 -> 10 | D30: USD | J30: =$I$5/$C$27 -> 280000 | K30: =$I$5/$C$27 -> 280000 | L30: =$I$5/$C$27 -> 280000 | M30: =$I$5/$C$27 -> 280000 | N30: =$I$5/$C$27 -> 280000 | O30: =$I$5/$C$27 -> 280000 | P30: =$I$5/$C$27 -> 280000
A31: ADDITION 5 | B31: CY-2031 | C31: =$C$5 -> 10 | D31: USD | K31: =$J$5/$C$27 -> 0 | L31: =$J$5/$C$27 -> 0 | M31: =$J$5/$C$27 -> 0 | N31: =$J$5/$C$27 -> 0 | O31: =$J$5/$C$27 -> 0 | P31: =$J$5/$C$27 -> 0
A32: ADDITION 6 | B32: CY-2032 | C32: =$C$5 -> 10 | D32: USD | L32: =$K$5/$C$27 -> 0 | M32: =$K$5/$C$27 -> 0 | N32: =$K$5/$C$27 -> 0 | O32: =$K$5/$C$27 -> 0 | P32: =$K$5/$C$27 -> 0
A33: ADDITION 7 | B33: CY-2033 | C33: =$C$5 -> 10 | D33: USD | M33: =$L$5/$C$27 -> 280000 | N33: =$L$5/$C$27 -> 280000 | O33: =$L$5/$C$27 -> 280000 | P33: =$L$5/$C$27 -> 280000
A34: ADDITION 8 | B34: CY-2034 | C34: =$C$5 -> 10 | D34: USD | N34: =$M$5/$C$27 -> 0 | O34: =$M$5/$C$27 -> 0 | P34: =$M$5/$C$27 -> 0
A35: ADDITION 9 | B35: CY-2035 | C35: =$C$5 -> 10 | D35: USD | O35: =$F$5/$C$27 -> 280000
A36: ADDITION 10 | B36: CY-2036 | C36: =$C$5 -> 10 | D36: USD
A37: TOTAL | F37: =SUM(F26:F36) -> 280000 | G37: =SUM(G26:G36) -> 560000 | H37: =SUM(H26:H36) -> 560000 | I37: =SUM(I26:I36) -> 840000 | J37: =SUM(J26:J36) -> 1120000 | K37: =SUM(K26:K36) -> 1120000 | L37: =SUM(L26:L36) -> 1120000 | M37: =SUM(M26:M36) -> 1400000 | ... P37: =SUM(P26:P36) -> 1400000
A38: SOFTWARE & PLATFORM DEVELOPMENT | B38: =E15 -> CY-2026 | C38: 8 | D38: USD | F38: =$E$6/$C$38 -> 125000 | G38: =$E$6/$C$38 -> 125000 | H38: =$E$6/$C$38 -> 125000 | I38: =$E$6/$C$38 -> 125000 | J38: =$E$6/$C$38 -> 125000 | K38: =$E$6/$C$38 -> 125000 | L38: =$E$6/$C$38 -> 125000 | M38: =$E$6/$C$38 -> 125000
A39: ADDITION 1 | B39: CY-2027 | C39: =$C$6 -> 8 | D39: USD | G39: =$F$6/$C$39 -> 62500 | H39: =$F$6/$C$39 -> 62500 | I39: =$F$6/$C$39 -> 62500 | J39: =$F$6/$C$39 -> 62500 | K39: =$F$6/$C$39 -> 62500 | L39: =$F$6/$C$39 -> 62500 | M39: =$F$6/$C$39 -> 62500 | N39: =$F$6/$C$39 -> 62500
A40: ADDITION 2 | B40: CY-2028 | C40: =$C$6 -> 8 | D40: USD | H40: =$G$6/$C$40 -> 62500 | I40: =$G$6/$C$40 -> 62500 | J40: =$G$6/$C$40 -> 62500 | K40: =$G$6/$C$40 -> 62500 | L40: =$G$6/$C$40 -> 62500 | M40: =$G$6/$C$40 -> 62500 | N40: =$G$6/$C$40 -> 62500 | O40: =$G$6/$C$40 -> 62500 | P40: =$G$6/$C$40 -> 62500
A41: ADDITION 3 | B41: CY-2029 | C41: =$C$6 -> 8 | D41: USD | I41: =$H$6/$C$41 -> 62500 | J41: =$I$6/$C$41 -> 62500 | K41: =$I$6/$C$41 -> 62500 | L41: =$I$6/$C$41 -> 62500 | M41: =$I$6/$C$41 -> 62500 | N41: =$I$6/$C$41 -> 62500 | O41: =$I$6/$C$41 -> 62500 | P41: =$I$6/$C$41 -> 62500
A42: ADDITION 4 | B42: CY-2030 | C42: =$C$6 -> 8 | D42: USD | J42: =$I$6/$C$42 -> 62500 | K42: =$I$6/$C$42 -> 62500 | L42: =$I$6/$C$42 -> 62500 | M42: =$I$6/$C$42 -> 62500 | N42: =$I$6/$C$42 -> 62500 | O42: =$I$6/$C$42 -> 62500 | P42: =$I$6/$C$42 -> 62500
A43: TOTAL | F43: =SUM(F38:F42) -> 125000 | G43: =SUM(G38:G42) -> 187500 | H43: =SUM(H38:H42) -> 250000 | I43: =SUM(I38:I42) -> 312500 | J43: =SUM(J38:J42) -> 375000 | K43: =SUM(K38:K42) -> 375000 | L43: =SUM(L38:L42) -> 375000 | M43: =SUM(M38:M42) -> 375000 | ... P43: =SUM(P38:P42) -> 187500
...

Sheet REVENUE PROJECTION
A1: A2 - E CHARGING & BATTERY SWAPPING - REVENUE PROJECTION
A2: DESCRIPTION | B2: UNIT | C2: CY-2027 | D2: CY-2028 | E2: CY-2029 | F2: CY-2030 | G2: CY-2031 | H2: CY-2032 | I2: CY-2033 | J2: CY-2034 | K2: CY-2035 | L2: CY-2036 | M2: CY-2037
A3: NO OF POWER UNITS SOLD | B3: KW | C3: ='POWER CALCULATIONS'!D27 -> 1.1449964e+08 | D3: ='POWER CALCULATIONS'!E27 -> 2.2899927e+08 | E3: ='POWER CALCULATIONS'!F27 -> 3.4349891e+08 | F3: ='POWER CALCULATIONS'!G27 -> 4.5799855e+08 | G3: ='POWER CALCULATIONS'!H27 -> 5.7249818e+08 | H3: ='POWER CALCULATIONS'!I27 -> 6.8699782e+08 | I3: ='POWER CALCULATIONS'!J27 -> 8.0181818e+08 | J3: ='POWER CALCULATIONS'!K27 -> 8.0181818e+08 | ... M3: ='POWER CALCULATIONS'!N27 -> 8.0181818e+08
A4: NUMBER OF USERS - SOFTWARE SUBSCRIPTION | B4: NUMBER | C4: ='ASSUMPTIONS_DATA'!D5 -> 714 | D4: ='ASSUMPTIONS_DATA'!E5+C4 -> 1428 | E4: ='ASSUMPTIONS_DATA'!F5+D4 -> 2142 | F4: ='ASSUMPTIONS_DATA'!G5+E4 -> 2856 | G4: ='ASSUMPTIONS_DATA'!H5+F4 -> 3570 | H4: ='ASSUMPTIONS_DATA'!I5+G4 -> 4284 | I4: ='ASSUMPTIONS_DATA'!J5+H4 -> 5000 | J4: ='ASSUMPTIONS_DATA'!K5+I4 -> 5000 | K4: ='ASSUMPTIONS_DATA'!L5+J4 -> 5000 | ... M4: ='ASSUMPTIONS_DATA'!N5+L4 -> 5000
A5: SALE PRICE PER UNIT | B5: USD | C5: ='POWER CALCULATIONS'!D29*3 -> 0.13548387 | D5: =C5*1.1 -> 0.14903226 | E5: =D5*1.1 -> 0.16393548 | F5: =E5*1.1 -> 0.18032903 | G5: =F5*1.1 -> 0.19836194 | H5: =G5*1.1 -> 0.21819813 | I5: =H5*1.1 -> 0.24001794 | J5: =I5*1.1 -> 0.26401974 | K5: =J5*1.1 -> 0.29042171 | ... M5: =L5*1.1 -> 0.35141027
A6: REVENUE FROM POWER SALES | B6: USD | C6: =C3*C5 -> 15512854 | D6: =D3*D5 -> 34128279 | E6: =E3*E5 -> 56311660 | F6: =F3*F5 -> 82590434 | G6: =G3*G5 -> 1.1356185e+08 | H6: =H3*H5 -> 1.4990164e+08 | I6: =I3*I5 -> 1.9245075e+08 | J6: =J3*J5 -> 2.1169582e+08 | ... M6: =M3*M5 -> 2.8176714e+08
A7: REVENUE FROM SUBSCRIPTIONS | B7: USD | C7: =C4*400 -> 285600 | D7: =D4*400 -> 571200 | E7: =E4*400 -> 856800 | F7: =F4*400 -> 1142400 | G7: =G4*400 -> 1428000 | H7: =H4*400 -> 1713600 | I7: =I4*400 -> 2000000 | J7: =J4*400 -> 2000000 | ... M7: =M4*400 -> 2000000

Sheet INCOME STATEMENT 
A1: A2 - E CHARGING & BATTERY SWAPPING - REVENUE PROJECTION
A2: DESCRIPTION | B2: UNIT | C2: CY-2026 | D2: CY-2027 | E2: CY-2028 | F2: CY-2029 | G2: CY-2030 | H2: CY-2031 | I2: CY-2032 | J2: CY-2033 | K2: CY-2034 | L2: CY-2035 | M2: CY-2036 | N2: CY-2037
A3: REVENUE | B3: USD | C3: 0 | D3: ='REVENUE PROJECTION'!C6 -> 15512854 | E3: ='REVENUE PROJECTION'!D6 -> 34128279 | F3: ='REVENUE PROJECTION'!E6 -> 56311660 | G3: ='REVENUE PROJECTION'!F6 -> 82590434 | H3: ='REVENUE PROJECTION'!G6 -> 1.1356185e+08 | I3: ='REVENUE PROJECTION'!H6 -> 1.4990164e+08 | J3: ='REVENUE PROJECTION'!I6 -> 1.9245075e+08 | K3: ='REVENUE PROJECTION'!J6 -> 2.1169582e+08 | ... N3: ='REVENUE PROJECTION'!M6 -> 2.8176714e+08
A4: LESS: COST OF POWER PURCHASE FROM EEP | B4: USD | C4: 0 | D4: ='POWER CALCULATIONS'!D30 -> 5170951.3 | E4: ='POWER CALCULATIONS'!E30 -> 11376093 | F4: ='POWER CALCULATIONS'!F30 -> 18770553 | G4: ='POWER CALCULATIONS'!G30 -> 27530145 | H4: ='POWER CALCULATIONS'!H30 -> 37853949 | I4: ='POWER CALCULATIONS'!I30 -> 49967213 | J4: ='POWER CALCULATIONS'!J30 -> 64150250 | K4: ='POWER CALCULATIONS'!K30 -> 70565275 | ... N4: ='POWER CALCULATIONS'!N30 -> 93922381
A5: GROSS MARGIN | B5: USD | C5: =C3-C4 -> 0 | D5: =D3-D4 -> 10341903 | E5: =E3-E4 -> 22752186 | F5: =F3-F4 -> 37541107 | G5: =G3-G4 -> 55060290 | H5: =H3-H4 -> 75707898 | I5: =I3-I4 -> 99934426 | J5: =J3-J4 -> 1.283005e+08 | ... N5: =N3-N4 -> 1.8784476e+08
A6: ADD: PLATFORM REVENUE ( SUBSCRIPTIONS) | B6: USD | C6: 0 | D6: ='REVENUE PROJECTION'!C7 -> 285600 | E6: ='REVENUE PROJECTION'!D7 -> 571200 | F6: ='REVENUE PROJECTION'!E7 -> 856800 | G6: ='REVENUE PROJECTION'!F7 -> 1142400 | H6: ='REVENUE PROJECTION'!G7 -> 1428000 | I6: ='REVENUE PROJECTION'!H7 -> 1713600 | J6: ='REVENUE PROJECTION'!I7 -> 2000000 | K6: ='REVENUE PROJECTION'!J7 -> 2000000 | ... N6: ='REVENUE PROJECTION'!M7 -> 2000000
A7: GROSS PROFIT | B7: USD | C7: =C5+C6 -> 0 | D7: =D5+D6 -> 10627503 | E7: =E5+E6 -> 23323386 | F7: =F5+F6 -> 38397907 | G7: =G5+G6 -> 56202690 | H7: =H5+H6 -> 77135898 | I7: =I5+I6 -> 1.0164803e+08 | J7: =J5+J6 -> 1.303005e+08 | ... N7: =N5+N6 -> 1.8984476e+08
A9: LESS: OPERATING EXPENSES | B9: USD | C9: 1000000 | D9: 3000000 | E9: =D9*1.2 -> 3600000 | F9: =E9*1.2 -> 4320000 | G9: =F9*1.2 -> 5184000 | H9: =G9*1.2 -> 6220800 | I9: =H9*1.2 -> 7464960 | J9: =I9*1.2 -> 8957952 | K9: =J9*1.2 -> 10749542 | L9: =K9*1.2 -> 12899451 | ... N9: =M9*1.2 -> 18575209
A10: LESS: VARIABLE OPEX (6% OF REVENUE) | B10: USD | C10: =C3*C9 -> 0 | D10: =D3*0.06 -> 930771.24 | E10: =E3*0.06 -> 2047696.7 | F10: =F3*0.06 -> 3378699.6 | G10: =G3*0.06 -> 4955426.1 | H10: =H3*0.06 -> 6813710.8 | I10: =I3*0.06 -> 8994098.3 | J10: =J3*0.06 -> 11547045 | K10: =K3*0.06 -> 12701749 | ... M10: =M3*0.06 -> 15369117 | N10: =M10*1.2 -> 18442940
A11: LESS: BATTERY LEASE CHARGES | B11: USD | C11: =C3*0.4 -> 0 | D11: =D3*0.35 -> 5429498.9 | E11: =E3*0.35 -> 11944898 | F11: =F3*0.35 -> 19709081 | G11: =G3*0.35 -> 28906652 | H11: =H3*0.35 -> 39746647 | I11: =I3*0.35 -> 52465574 | J11: =J3*0.35 -> 67357762 | K11: =K3*0.35 -> 74093539 | ... N11: =N3*0.35 -> 98618500
A12: EBITDA | B12: USD | C12: =C7-C9-C10-C11 -> -1000000 | D12: =D7-D9-D10-D11 -> 1267232.5 | E12: =E7-E9-E10-E11 -> 5730791.5 | F12: =F7-F9-F10-F11 -> 10990126 | G12: =G7-G9-G10-G11 -> 17156612 | H12: =H7-H9-H10-H11 -> 24354741 | I12: =I7-I9-I10-I11 -> 32723394 | J12: =J7-J9-J10-J11 -> 42437740 | ... N12: =N7-N9-N10-N11 -> 54208112
A13: DEPRECIATION | B13: USD | C13: ='CAPEX & DEPRECIATION'!E10 -> 0 | D13: ='CAPEX & DEPRECIATION'!F10 -> 2038333.3 | E13: ='CAPEX & DEPRECIATION'!G10 -> 4080833.3 | F13: ='CAPEX & DEPRECIATION'!H10 -> 6693333.3 | G13: ='CAPEX & DEPRECIATION'!I10 -> 10435833 | H13: ='CAPEX & DEPRECIATION'!J10 -> 15028333 | I13: ='CAPEX & DEPRECIATION'!K10 -> 19278333 | J13: ='CAPEX & DEPRECIATION'!L10 -> 24378333 | ... N13: ='CAPEX & DEPRECIATION'!P10 -> 24545833
A14: EBT | B14: USD | C14: =C12-C13 -> -1000000 | D14: =D12-D13 -> -771100.82 | E14: =E12-E13 -> 1649958.2 | F14: =F12-F13 -> 4296792.7 | G14: =G12-G13 -> 6720778.2 | H14: =H12-H13 -> 9326407.5 | I14: =I12-I13 -> 13445061 | J14: =J12-J13 -> 18059407 | ... N14: =N12-N13 -> 29662279
A15: TAX @ 30% | B15: USD | C15: 0 | D15: 0 | E15: =E14*0.3 -> 494987.46 | F15: =F14*0.3 -> 1289037.8 | G15: =G14*0.3 -> 2016233.5 | H15: =H14*0.3 -> 2797922.3 | I15: =I14*0.3 -> 4033518.2 | J15: =J14*0.3 -> 5417822.1 | K15: =K14*0.3 -> 6195715.8 | L15: =L14*0.3 -> 7218301.1 | M15: =M14*0.3 -> 8172147.7 | N15: =M15*1.2 -> 9806577.2
A17: EAT (NET INCOME) | B17: USD | C17: =C14-C15 -> -1000000 | D17: =D14-D15 -> -771100.82 | E17: =E14-E15 -> 1154970.7 | F17: =F14-F15 -> 3007754.9 | G17: =G14-G15 -> 4704544.7 | H17: =H14-H15 -> 6528485.3 | I17: =I14-I15 -> 9411542.4 | J17: =J14-J15 -> 12641585 | ... N17: =N14-N15 -> 19855702
A20: CUMULATIVE EAT | B20: USD | D20: =D17 -> -771100.82 | E20: =D20+E17 -> 383869.92 | F20: =E20+F17 -> 3391624.8 | G20: =F20+G17 -> 8096169.5 | H20: =G20+H17 -> 14624655 | I20: =H20+I17 -> 24036197 | J20: =I20+J17 -> 36677782 | K20: =J20+K17 -> 51134452 | L20: =K20+L17 -> 67977155 | ... N20: =M20+N17 -> 1.069012e+08
A21: RATE OF RETURN | B21: % | C21: =C17/'SOURCE_USE OF FUNDS'!C6 -> -0.03030303 | D21: =D17/'SOURCE_USE OF FUNDS'!D6 -> -0.011224175 | E21: =E17/'SOURCE_USE OF FUNDS'!E6 -> 0.010814333 | F21: =F17/'SOURCE_USE OF FUNDS'!F6 -> 0.019048479 | G21: =G17/'SOURCE_USE OF FUNDS'!G6 -> 0.021462339 | H21: =H17/'SOURCE_USE OF FUNDS'!H6 -> 0.022715676 | I21: =I17/'SOURCE_USE OF FUNDS'!I6 -> 0.030887898 | J21: =J17/'SOURCE_USE OF FUNDS'!J6 -> 0.041110845 | ... N21: =N17/'SOURCE_USE OF FUNDS'!N6 -> 0.064571388 | O21: EXIT VALUE
A22: INVESTOR EAT (NET INCOME) 25% | B22: USD | C22: =('SOURCE_USE OF FUNDS'!C6*-1)+C17 -> -34000000 | D22: =D17*0.25 -> -192775.2 | E22: =E17*0.25 -> 288742.69 | F22: =F17*0.25 -> 751938.72 | G22: =G17*0.25 -> 1176136.2 | H22: =H17*0.25 -> 1632121.3 | I22: =I17*0.25 -> 2352885.6 | J22: =J17*0.25 -> 3160396.2 | K22: =K17*0.25 -> 3614167.5 | ... N22: =N17*0.25 -> 4963925.5 | O22: ='VALUATION SUMMARY'!H8 -> 1.6262434e+08
A23: INVESTOR RATE OF RETURN 25% | B23: % | C23: =(C17*0.25)/'SOURCE_USE OF FUNDS'!C6 -> -0.0075757576 | D23: =(D17*0.25)/'SOURCE_USE OF FUNDS'!D6 -> -0.0028060437 | E23: =(E17*0.25)/'SOURCE_USE OF FUNDS'!E6 -> 0.0027035832 | F23: =(F17*0.25)/'SOURCE_USE OF FUNDS'!F6 -> 0.0047621198 | G23: =(G17*0.25)/'SOURCE_USE OF FUNDS'!G6 -> 0.0053655848 | H23: =(H17*0.25)/'SOURCE_USE OF FUNDS'!H6 -> 0.005678919 | I23: =(I17*0.25)/'SOURCE_USE OF FUNDS'!I6 -> 0.0077219744 | J23: =(J17*0.25)/'SOURCE_USE OF FUNDS'!J6 -> 0.010277711 | ... N23: =(N17*0.25)/'SOURCE_USE OF FUNDS'!N6 -> 0.016142847
A24: IRR | B24: % | C24: =IRR(C22:O22,0.18) -> 0.16517774

Sheet CASH FLOW
A1: A2 - E CHARGING & BATTERY SWAPPING - REVENUE PROJECTION
A2: DESCRIPTION | B2: UNIT | C2: CY-2026 | D2: CY-2027 | E2: CY-2028 | F2: CY-2029 | G2: CY-2030 | H2: CY-2031 | I2: CY-2032 | J2: CY-2033 | K2: CY-2034 | L2: CY-2035 | M2: CY-2036 | N2: CY-2037
A3: OPERATING ACTIVITIES
A4: NET INCOME | B4: USD | C4: ='INCOME STATEMENT '!C17 -> -1000000 | D4: ='INCOME STATEMENT '!D17 -> -771100.82 | E4: ='INCOME STATEMENT '!E17 -> 1154970.7 | F4: ='INCOME STATEMENT '!F17 -> 3007754.9 | G4: ='INCOME STATEMENT '!G17 -> 4704544.7 | H4: ='INCOME STATEMENT '!H17 -> 6528485.3 | I4: ='INCOME STATEMENT '!I17 -> 9411542.4 | J4: ='INCOME STATEMENT '!J17 -> 12641585 | ... N4: ='INCOME STATEMENT '!N17 -> 19855702
A5: ADD: DEPRECIATION | B5: USD | C5: ='CAPEX & DEPRECIATION'!E10 -> 0 | D5: ='CAPEX & DEPRECIATION'!F10 -> 2038333.3 | E5: ='CAPEX & DEPRECIATION'!G10 -> 4080833.3 | F5: ='CAPEX & DEPRECIATION'!H10 -> 6693333.3 | G5: ='CAPEX & DEPRECIATION'!I10 -> 10435833 | H5: ='CAPEX & DEPRECIATION'!J10 -> 15028333 | I5: ='CAPEX & DEPRECIATION'!K10 -> 19278333 | J5: ='CAPEX & DEPRECIATION'!L10 -> 24378333 | ... N5: ='CAPEX & DEPRECIATION'!P10 -> 24545833
A6: NET CASH FROM OPERATIONS | B6: USD | C6: =C4+C5 -> -1000000 | D6: =D4+D5 -> 1267232.5 | E6: =E4+E5 -> 5235804.1 | F6: =F4+F5 -> 9701088.2 | G6: =G4+G5 -> 15140378 | H6: =H4+H5 -> 21556819 | I6: =I4+I5 -> 28689876 | J6: =J4+J5 -> 37019918 | ... N6: =N4+N5 -> 44401535
A8: INVESTING ACTIVITIES
A9: CAPEX | B9: USD | C9: ='CAPEX & DEPRECIATION'!E8*-1 -> -23000000 | D9: ='CAPEX & DEPRECIATION'!F8*-1 -> -30700000 | E9: ='CAPEX & DEPRECIATION'!G8*-1 -> -38100000 | F9: ='CAPEX & DEPRECIATION'!H8*-1 -> -51100000 | G9: ='CAPEX & DEPRECIATION'!I8*-1 -> -61300000 | H9: ='CAPEX & DEPRECIATION'!J8*-1 -> -68200000 | I9: ='CAPEX & DEPRECIATION'!K8*-1 -> -17300000 | J9: ='CAPEX & DEPRECIATION'!L8*-1 -> -2800000 | ... N9: ='CAPEX & DEPRECIATION'!P8*-1 -> 0
A10: NET CASH FROM INVESTING | B10: USD | C10: =SUM(C9) -> -23000000 | D10: =SUM(D9) -> -30700000 | E10: =SUM(E9) -> -38100000 | F10: =SUM(F9) -> -51100000 | G10: =SUM(G9) -> -61300000 | H10: =SUM(H9) -> -68200000 | I10: =SUM(I9) -> -17300000 | J10: =SUM(J9) -> -2800000 | ... N10: =SUM(N9) -> 0
A12: FINANCING ACTIVITIES
A13: EQUITY INJECTION | B13: USD | C13: ='SOURCE_USE OF FUNDS'!C5 -> 33000000 | D13: ='SOURCE_USE OF FUNDS'!D5 -> 35700000 | E13: ='SOURCE_USE OF FUNDS'!E5 -> 38100000 | F13: ='SOURCE_USE OF FUNDS'!F5 -> 51100000 | G13: ='SOURCE_USE OF FUNDS'!G5 -> 61300000 | H13: ='SOURCE_USE OF FUNDS'!H5 -> 68200000 | I13: ='SOURCE_USE OF FUNDS'!I5 -> 17300000 | J13: ='SOURCE_USE OF FUNDS'!J5 -> 2800000 | ... N13: ='SOURCE_USE OF FUNDS'!N5 -> 0
A14: DIVIDEND | B14: % | C14: 0 | D14: 0 | E14: 0 | F14: 0 | G14: 0 | H14: 0 | I14: 0 | J14: 0 | K14: 0 | L14: 0 | M14: 0 | N14: 0
A15: DIVIDEND | B15: USD | C15: =(C4*C14)*-1 -> 0 | D15: =(D4*D14)*-1 -> 0 | E15: =(E4*E14)*-1 -> 0 | F15: =(F4*F14)*-1 -> 0 | G15: =(G4*G14)*-1 -> 0 | H15: =(H4*H14)*-1 -> 0 | I15: =(I4*I14)*-1 -> 0 | J15: =(J4*J14)*-1 -> 0 | ... N15: =(N4*N14)*-1 -> 0
A16: DIVIDEND TAX @ 15% | B16: USD | C16: =C15*0.15 -> 0 | D16: =D15*0.15 -> 0 | E16: =E15*0.15 -> 0 | F16: =F15*0.15 -> 0 | G16: =G15*0.15 -> 0 | H16: =H15*0.15 -> 0 | I16: =I15*0.15 -> 0 | J16: =J15*0.15 -> 0 | ... N16: =N15*0.15 -> 0
A17: NET CASH FROM FINANCING | B17: USD | C17: =SUM(C15:C16)+C13 -> 33000000 | D17: =SUM(D15:D16)+D13 -> 35700000 | E17: =SUM(E15:E16)+E13 -> 38100000 | F17: =SUM(F15:F16)+F13 -> 51100000 | G17: =SUM(G15:G16)+G13 -> 61300000 | H17: =SUM(H15:H16)+H13 -> 68200000 | I17: =SUM(I15:I16)+I13 -> 17300000 | J17: =SUM(J15:J16)+J13 -> 2800000 | ... N17: =SUM(N15:N16)+N13 -> 0
A19: NET CHANGE IN CASH | B19: USD | C19: =C17+C10+C6 -> 9000000 | D19: =D17+D10+D6 -> 6267232.5 | E19: =E17+E10+E6 -> 5235804.1 | F19: =F17+F10+F6 -> 9701088.2 | G19: =G17+G10+G6 -> 15140378 | H19: =H17+H10+H6 -> 21556819 | I19: =I17+I10+I6 -> 28689876 | J19: =J17+J10+J6 -> 37019918 | ... N19: =N17+N10+N6 -> 44401535
A21: CASH-OPENING BALANCE | B21: USD | C21: 0 | D21: =C22 -> 9000000 | E21: =D22 -> 15267233 | F21: =E22 -> 20503037 | G21: =F22 -> 30204125 | H21: =G22 -> 45344503 | I21: =H22 -> 66901321 | J21: =I22 -> 95591197 | K21: =J22 -> 1.3261112e+08 | ... N21: =M22 -> 2.5774633e+08
A22: CASH-CLOSING BALANCE | B22: USD | C22: =C17+C10+C6 -> 9000000 | D22: =D19+D21 -> 15267233 | E22: =E19+E21 -> 20503037 | F22: =F19+F21 -> 30204125 | G22: =G19+G21 -> 45344503 | H22: =H19+H21 -> 66901321 | I22: =I19+I21 -> 95591197 | J22: =J19+J21 -> 1.3261112e+08 | K22: =K19+K21 -> 1.7200112e+08 | ... N22: =N19+N21 -> 3.0214787e+08
